<!DOCTYPE html>
<html lang="en">
  <head>
    <meta charset="UTF-8" />
    <meta name="viewport" content="width=device-width, initial-scale=1.0" />
    <meta http-equiv="X-UA-Compatible" content="ie=edge" />
    <title>Promise与异步编程</title>
  </head>
  <body>
    <script>
      const fetch = (f, duration, message, rejected = false) => {
        return new Promise((resolve, reject) => {
            console.log('init') // promise 执行器此时是同步操作, 立即执行
          setTimeout(() => {
            console.log(message);
            !rejected ? resolve(f()) : reject(f());
          }, duration * 1000);
        });
      };
      let promise = fetch(() => 1, 0, '1s duration')
      promise.then(x => {
          console.log('0s called',x, promise)
          promise.then(x => {
              console.log('0s called', x)
          }) 
      })
      console.log(111) // 在同一次事件循环中, 同步远远大于异步操作
      console.log('')
      let list = [
          fetch(() => 1, 1, '1s duration', true),
          fetch(() => 2, 2, '2s duration', true),
          fetch(() => 3, 3, '3s duration', true)
      ]
      // 当正常的时候 运行需要花最长的时间, 此例子中为 3s
      // 当异常的时候, 所有的请求都正常发出去, 此时 then 不能正常输出, catch 可以 catch 到第一个发生错误的请求
      Promise.all(list).then(messages => console.log(messages)).catch(e => console.log('error',e))
    </script>
  </body>
</html>
